Traceback (most recent call last):
  File "/usr/lib/python3/dist-packages/urllib3/connection.py", line 169, in _new_conn
    conn = connection.create_connection(
  File "/usr/lib/python3/dist-packages/urllib3/util/connection.py", line 73, in create_connection
    for res in socket.getaddrinfo(host, port, family, socket.SOCK_STREAM):
  File "/usr/lib/python3.10/socket.py", line 955, in getaddrinfo
    for res in _socket.getaddrinfo(host, port, family, type, proto, flags):
socket.gaierror: [Errno -2] Name or service not known

During handling of the above exception, another exception occurred:

Traceback (most recent call last):
  File "/usr/lib/python3/dist-packages/urllib3/connectionpool.py", line 699, in urlopen
    httplib_response = self._make_request(
  File "/usr/lib/python3/dist-packages/urllib3/connectionpool.py", line 382, in _make_request
    self._validate_conn(conn)
  File "/usr/lib/python3/dist-packages/urllib3/connectionpool.py", line 1012, in _validate_conn
    conn.connect()
  File "/usr/lib/python3/dist-packages/urllib3/connection.py", line 353, in connect
    conn = self._new_conn()
  File "/usr/lib/python3/dist-packages/urllib3/connection.py", line 181, in _new_conn
    raise NewConnectionError(
urllib3.exceptions.NewConnectionError: <urllib3.connection.HTTPSConnection object at 0x7f955bfbeda0>: Failed to establish a new connection: [Errno -2] Name or service not known

During handling of the above exception, another exception occurred:

Traceback (most recent call last):
  File "/usr/lib/python3/dist-packages/requests/adapters.py", line 439, in send
    resp = conn.urlopen(
  File "/usr/lib/python3/dist-packages/urllib3/connectionpool.py", line 783, in urlopen
    return self.urlopen(
  File "/usr/lib/python3/dist-packages/urllib3/connectionpool.py", line 783, in urlopen
    return self.urlopen(
  File "/usr/lib/python3/dist-packages/urllib3/connectionpool.py", line 783, in urlopen
    return self.urlopen(
  File "/usr/lib/python3/dist-packages/urllib3/connectionpool.py", line 755, in urlopen
    retries = retries.increment(
  File "/usr/lib/python3/dist-packages/urllib3/util/retry.py", line 574, in increment
    raise MaxRetryError(_pool, url, error or ResponseError(cause))
urllib3.exceptions.MaxRetryError: HTTPSConnectionPool(host='oauth2.googleapis.com', port=443): Max retries exceeded with url: /token (Caused by NewConnectionError('<urllib3.connection.HTTPSConnection object at 0x7f955bfbeda0>: Failed to establish a new connection: [Errno -2] Name or service not known'))

During handling of the above exception, another exception occurred:

Traceback (most recent call last):
  File "/home/afterchange/.local/lib/python3.10/site-packages/google/auth/transport/requests.py", line 193, in __call__
    response = self.session.request(
  File "/usr/lib/python3/dist-packages/requests/sessions.py", line 542, in request
    resp = self.send(prep, **send_kwargs)
  File "/usr/lib/python3/dist-packages/requests/sessions.py", line 655, in send
    r = adapter.send(request, **kwargs)
  File "/usr/lib/python3/dist-packages/requests/adapters.py", line 516, in send
    raise ConnectionError(e, request=request)
requests.exceptions.ConnectionError: HTTPSConnectionPool(host='oauth2.googleapis.com', port=443): Max retries exceeded with url: /token (Caused by NewConnectionError('<urllib3.connection.HTTPSConnection object at 0x7f955bfbeda0>: Failed to establish a new connection: [Errno -2] Name or service not known'))

The above exception was the direct cause of the following exception:

Traceback (most recent call last):
  File "/home/afterchange/Downloads/Leetcode-Grind-Automation/resetTally.py", line 2, in <module>
    import Sheets_API_Interface as Sheets
  File "/home/afterchange/Downloads/Leetcode-Grind-Automation/Sheets_API_Interface.py", line 26, in <module>
    sheet = client.open("LC Automated").worksheets()
  File "/home/afterchange/.local/lib/python3.10/site-packages/gspread/client.py", line 152, in open
    self.list_spreadsheet_files(title, folder_id),
  File "/home/afterchange/.local/lib/python3.10/site-packages/gspread/client.py", line 127, in list_spreadsheet_files
    res = self.request("get", url, params=params).json()
  File "/home/afterchange/.local/lib/python3.10/site-packages/gspread/client.py", line 79, in request
    response = getattr(self.session, method)(
  File "/usr/lib/python3/dist-packages/requests/sessions.py", line 555, in get
    return self.request('GET', url, **kwargs)
  File "/home/afterchange/.local/lib/python3.10/site-packages/google/auth/transport/requests.py", line 545, in request
    self.credentials.before_request(auth_request, method, url, request_headers)
  File "/home/afterchange/.local/lib/python3.10/site-packages/google/auth/credentials.py", line 133, in before_request
    self.refresh(request)
  File "/home/afterchange/.local/lib/python3.10/site-packages/google/oauth2/service_account.py", line 410, in refresh
    access_token, expiry, _ = _client.jwt_grant(
  File "/home/afterchange/.local/lib/python3.10/site-packages/google/oauth2/_client.py", line 289, in jwt_grant
    response_data = _token_endpoint_request(
  File "/home/afterchange/.local/lib/python3.10/site-packages/google/oauth2/_client.py", line 250, in _token_endpoint_request
    response_status_ok, response_data, retryable_error = _token_endpoint_request_no_throw(
  File "/home/afterchange/.local/lib/python3.10/site-packages/google/oauth2/_client.py", line 199, in _token_endpoint_request_no_throw
    request_succeeded, response_data, retryable_error = _perform_request()
  File "/home/afterchange/.local/lib/python3.10/site-packages/google/oauth2/_client.py", line 175, in _perform_request
    response = request(
  File "/home/afterchange/.local/lib/python3.10/site-packages/google/auth/transport/requests.py", line 199, in __call__
    six.raise_from(new_exc, caught_exc)
  File "<string>", line 3, in raise_from
google.auth.exceptions.TransportError: HTTPSConnectionPool(host='oauth2.googleapis.com', port=443): Max retries exceeded with url: /token (Caused by NewConnectionError('<urllib3.connection.HTTPSConnection object at 0x7f955bfbeda0>: Failed to establish a new connection: [Errno -2] Name or service not known'))
